[2025-10-13T10:18:46.889+0000] {local_task_job_runner.py:123} INFO - ::group::Pre task execution logs
[2025-10-13T10:18:46.992+0000] {taskinstance.py:2603} INFO - Dependencies all met for dep_context=non-requeueable deps ti=<TaskInstance: LocalIngestionDAG.get_data_task manual__2025-10-13T10:18:05.974843+00:00 [queued]>
[2025-10-13T10:18:47.035+0000] {taskinstance.py:2603} INFO - Dependencies all met for dep_context=requeueable deps ti=<TaskInstance: LocalIngestionDAG.get_data_task manual__2025-10-13T10:18:05.974843+00:00 [queued]>
[2025-10-13T10:18:47.037+0000] {taskinstance.py:2856} INFO - Starting attempt 1 of 1
[2025-10-13T10:18:47.097+0000] {taskinstance.py:2879} INFO - Executing <Task(PythonOperator): get_data_task> on 2025-10-13 10:18:05.974843+00:00
[2025-10-13T10:18:47.134+0000] {warnings.py:112} WARNING - /home/***/.local/lib/python3.12/site-packages/***/task/task_runner/standard_task_runner.py:70: DeprecationWarning: This process (pid=3627) is multi-threaded, use of fork() may lead to deadlocks in the child.
  pid = os.fork()

[2025-10-13T10:18:47.144+0000] {standard_task_runner.py:72} INFO - Started process 3635 to run task
[2025-10-13T10:18:47.142+0000] {standard_task_runner.py:104} INFO - Running: ['***', 'tasks', 'run', 'LocalIngestionDAG', 'get_data_task', 'manual__2025-10-13T10:18:05.974843+00:00', '--job-id', '85', '--raw', '--subdir', 'DAGS_FOLDER/ingest_to_db.py', '--cfg-path', '/tmp/tmpwopi563u']
[2025-10-13T10:18:47.149+0000] {standard_task_runner.py:105} INFO - Job 85: Subtask get_data_task
[2025-10-13T10:18:47.308+0000] {task_command.py:467} INFO - Running <TaskInstance: LocalIngestionDAG.get_data_task manual__2025-10-13T10:18:05.974843+00:00 [running]> on host 1fb6d74705f4
[2025-10-13T10:18:47.486+0000] {taskinstance.py:3122} INFO - Exporting env vars: AIRFLOW_CTX_DAG_OWNER='***' AIRFLOW_CTX_DAG_ID='LocalIngestionDAG' AIRFLOW_CTX_TASK_ID='get_data_task' AIRFLOW_CTX_EXECUTION_DATE='2025-10-13T10:18:05.974843+00:00' AIRFLOW_CTX_TRY_NUMBER='1' AIRFLOW_CTX_DAG_RUN_ID='manual__2025-10-13T10:18:05.974843+00:00'
[2025-10-13T10:18:47.489+0000] {taskinstance.py:731} INFO - ::endgroup::
[2025-10-13T10:18:48.493+0000] {logging_mixin.py:190} INFO - https://api.aviationstack.com/v1/airplanes?limit=1&offset=486&access_key=0b2975d7a8b55cefc9c837abf63c1bc4
[2025-10-13T10:18:48.929+0000] {logging_mixin.py:190} INFO - {'id': '9586177', 'iata_type': 'EMB170-100', 'airplane_id': '487', 'airline_iata_code': '5D', 'iata_code_long': 'E170', 'iata_code_short': 'E70', 'airline_icao_code': None, 'construction_number': '17000141', 'delivery_date': '2006-08-26T22:00:00.000Z', 'engines_count': '2', 'engines_type': 'JET', 'first_flight_date': '2000-06-07T22:00:00.000Z', 'icao_code_hex': '0D0253', 'line_number': None, 'model_code': 'EMB 170-100STD', 'registration_number': 'XA-GAM', 'test_registration_number': None, 'plane_age': '17', 'plane_class': None, 'model_name': 'Emb-170', 'plane_owner': 'Aeromexico', 'plane_series': '100ST', 'plane_status': 'active', 'production_line': 'Embraer EMB-170/EMB-', 'registration_date': '2014-07-31T22:00:00.000Z', 'rollout_date': '2000-06-06T22:00:00.000Z'}
[2025-10-13T10:18:49.189+0000] {logging_mixin.py:190} INFO - {'photos': [{'id': '750638', 'thumbnail': {'src': 'https://t.plnspttrs.net/24375/750638_9a9d52a9a8_t.jpg', 'size': {'width': 200, 'height': 133}}, 'thumbnail_large': {'src': 'https://t.plnspttrs.net/24375/750638_9a9d52a9a8_280.jpg', 'size': {'width': 420, 'height': 280}}, 'link': 'https://www.planespotters.net/photo/750638/xa-gam-aeromexico-connect-embraer-erj-170lr-erj-170-100-lr?utm_source=api', 'photographer': 'Gabriel Mora Aldama '}]}
[2025-10-13T10:18:49.190+0000] {logging_mixin.py:190} INFO - {'engines_count': '2', 'engines_type': 'JET', 'first_flight_date': '2000-06-07T22:00:00.000Z', 'owner': 'Aeromexico', 'registration_number': 'XA-GAM', 'model': 'EMB 170-100STD', 'production_line': 'Embraer EMB-170/EMB-', 'status': 'active', 'image': 'https://t.plnspttrs.net/24375/750638_9a9d52a9a8_280.jpg', 'photographer': 'Gabriel Mora Aldama '}
[2025-10-13T10:18:49.192+0000] {taskinstance.py:3301} ERROR - Task failed with exception
Traceback (most recent call last):
  File "/home/airflow/.local/lib/python3.12/site-packages/airflow/models/taskinstance.py", line 767, in _execute_task
    result = _execute_callable(context=context, **execute_callable_kwargs)
             ^^^^^^^^^^^^^^^^^^^^^^^^^^^^^^^^^^^^^^^^^^^^^^^^^^^^^^^^^^^^^
  File "/home/airflow/.local/lib/python3.12/site-packages/airflow/models/taskinstance.py", line 733, in _execute_callable
    return ExecutionCallableRunner(
           ^^^^^^^^^^^^^^^^^^^^^^^^
  File "/home/airflow/.local/lib/python3.12/site-packages/airflow/utils/operator_helpers.py", line 252, in run
    return self.func(*args, **kwargs)
           ^^^^^^^^^^^^^^^^^^^^^^^^^^
  File "/home/airflow/.local/lib/python3.12/site-packages/airflow/models/baseoperator.py", line 406, in wrapper
    return func(self, *args, **kwargs)
           ^^^^^^^^^^^^^^^^^^^^^^^^^^^
  File "/home/airflow/.local/lib/python3.12/site-packages/airflow/operators/python.py", line 238, in execute
    return_value = self.execute_callable()
                   ^^^^^^^^^^^^^^^^^^^^^^^
  File "/home/airflow/.local/lib/python3.12/site-packages/airflow/operators/python.py", line 256, in execute_callable
    return runner.run(*self.op_args, **self.op_kwargs)
           ^^^^^^^^^^^^^^^^^^^^^^^^^^^^^^^^^^^^^^^^^^^
  File "/home/airflow/.local/lib/python3.12/site-packages/airflow/utils/operator_helpers.py", line 252, in run
    return self.func(*args, **kwargs)
           ^^^^^^^^^^^^^^^^^^^^^^^^^^
  File "/opt/airflow/dags/ingest_to_db.py", line 82, in get_data
    today = datetime.today().strftime('%d-%m-%Y')
            ^^^^^^^^^^^^^^
AttributeError: module 'datetime' has no attribute 'today'
[2025-10-13T10:18:49.229+0000] {taskinstance.py:1225} INFO - Marking task as FAILED. dag_id=LocalIngestionDAG, task_id=get_data_task, run_id=manual__2025-10-13T10:18:05.974843+00:00, execution_date=20251013T101805, start_date=20251013T101846, end_date=20251013T101849
[2025-10-13T10:18:49.367+0000] {taskinstance.py:340} INFO - ::group::Post task execution logs
[2025-10-13T10:18:49.368+0000] {standard_task_runner.py:124} ERROR - Failed to execute job 85 for task get_data_task (module 'datetime' has no attribute 'today'; 3635)
Traceback (most recent call last):
  File "/home/airflow/.local/lib/python3.12/site-packages/airflow/task/task_runner/standard_task_runner.py", line 117, in _start_by_fork
    ret = args.func(args, dag=self.dag)
          ^^^^^^^^^^^^^^^^^^^^^^^^^^^^^
  File "/home/airflow/.local/lib/python3.12/site-packages/airflow/cli/cli_config.py", line 49, in command
    return func(*args, **kwargs)
           ^^^^^^^^^^^^^^^^^^^^^
  File "/home/airflow/.local/lib/python3.12/site-packages/airflow/utils/cli.py", line 115, in wrapper
    return f(*args, **kwargs)
           ^^^^^^^^^^^^^^^^^^
  File "/home/airflow/.local/lib/python3.12/site-packages/airflow/cli/commands/task_command.py", line 483, in task_run
    task_return_code = _run_task_by_selected_method(args, _dag, ti)
                       ^^^^^^^^^^^^^^^^^^^^^^^^^^^^^^^^^^^^^^^^^^^^
  File "/home/airflow/.local/lib/python3.12/site-packages/airflow/cli/commands/task_command.py", line 256, in _run_task_by_selected_method
    return _run_raw_task(args, ti)
           ^^^^^^^^^^^^^^^^^^^^^^^
  File "/home/airflow/.local/lib/python3.12/site-packages/airflow/cli/commands/task_command.py", line 341, in _run_raw_task
    return ti._run_raw_task(
           ^^^^^^^^^^^^^^^^^
  File "/home/airflow/.local/lib/python3.12/site-packages/airflow/utils/session.py", line 97, in wrapper
    return func(*args, session=session, **kwargs)
           ^^^^^^^^^^^^^^^^^^^^^^^^^^^^^^^^^^^^^^
  File "/home/airflow/.local/lib/python3.12/site-packages/airflow/models/taskinstance.py", line 2995, in _run_raw_task
    return _run_raw_task(
           ^^^^^^^^^^^^^^
  File "/home/airflow/.local/lib/python3.12/site-packages/airflow/models/taskinstance.py", line 273, in _run_raw_task
    TaskInstance._execute_task_with_callbacks(
  File "/home/airflow/.local/lib/python3.12/site-packages/airflow/models/taskinstance.py", line 3149, in _execute_task_with_callbacks
    result = self._execute_task(context, task_orig)
             ^^^^^^^^^^^^^^^^^^^^^^^^^^^^^^^^^^^^^^
  File "/home/airflow/.local/lib/python3.12/site-packages/airflow/models/taskinstance.py", line 3173, in _execute_task
    return _execute_task(self, context, task_orig)
           ^^^^^^^^^^^^^^^^^^^^^^^^^^^^^^^^^^^^^^^
  File "/home/airflow/.local/lib/python3.12/site-packages/airflow/models/taskinstance.py", line 767, in _execute_task
    result = _execute_callable(context=context, **execute_callable_kwargs)
             ^^^^^^^^^^^^^^^^^^^^^^^^^^^^^^^^^^^^^^^^^^^^^^^^^^^^^^^^^^^^^
  File "/home/airflow/.local/lib/python3.12/site-packages/airflow/models/taskinstance.py", line 733, in _execute_callable
    return ExecutionCallableRunner(
           ^^^^^^^^^^^^^^^^^^^^^^^^
  File "/home/airflow/.local/lib/python3.12/site-packages/airflow/utils/operator_helpers.py", line 252, in run
    return self.func(*args, **kwargs)
           ^^^^^^^^^^^^^^^^^^^^^^^^^^
  File "/home/airflow/.local/lib/python3.12/site-packages/airflow/models/baseoperator.py", line 406, in wrapper
    return func(self, *args, **kwargs)
           ^^^^^^^^^^^^^^^^^^^^^^^^^^^
  File "/home/airflow/.local/lib/python3.12/site-packages/airflow/operators/python.py", line 238, in execute
    return_value = self.execute_callable()
                   ^^^^^^^^^^^^^^^^^^^^^^^
  File "/home/airflow/.local/lib/python3.12/site-packages/airflow/operators/python.py", line 256, in execute_callable
    return runner.run(*self.op_args, **self.op_kwargs)
           ^^^^^^^^^^^^^^^^^^^^^^^^^^^^^^^^^^^^^^^^^^^
  File "/home/airflow/.local/lib/python3.12/site-packages/airflow/utils/operator_helpers.py", line 252, in run
    return self.func(*args, **kwargs)
           ^^^^^^^^^^^^^^^^^^^^^^^^^^
  File "/opt/airflow/dags/ingest_to_db.py", line 82, in get_data
    today = datetime.today().strftime('%d-%m-%Y')
            ^^^^^^^^^^^^^^
AttributeError: module 'datetime' has no attribute 'today'
[2025-10-13T10:18:49.429+0000] {local_task_job_runner.py:261} INFO - Task exited with return code 1
[2025-10-13T10:18:49.500+0000] {taskinstance.py:3891} INFO - 0 downstream tasks scheduled from follow-on schedule check
[2025-10-13T10:18:49.646+0000] {local_task_job_runner.py:240} INFO - ::endgroup::
